Workbook

Sheet Summer Comp
A1: NEWCASTLE TABLE TENNIS - SUMMER COMP 2026 - From Feb 16 / 18
B2: PLAYERS | C2: RATING | D2: PAID $5 | E2: PAID NSW | F2: NOTES | I2: RESERVES | J2: RATING | K2: RATING
A3: 1 | B3: Williams, Peter | C3: 1512 | D3: FALSE | E3: FALSE | H3: 1 | I3: Connor, Christina | J3: 1374 | K3: 986
A4: 2 | B4: Barrett, Scott | C4: 1483 | D4: FALSE | E4: FALSE | H4: 2 | J4: 1110
A5: 3 | B5: Shrestha, Harish | C5: 1288 | D5: FALSE | E5: FALSE | H5: 3 | J5: 995
A6: 4 | B6: Jenkinson, Chris | C6: 1282 | D6: FALSE | E6: FALSE | H6: 4 | J6: 946
A7: 5 | B7: Rhodes, Michael | C7: 1215 | D7: FALSE | E7: FALSE | H7: 5 | J7: 944
A8: 6 | B8: Genet, Richard | C8: 1193 | D8: FALSE | E8: FALSE | F8: Share spot | H8: 6 | J8: 706
A9: 7 | B9: Saperas, George | C9: 1188 | D9: FALSE | E9: FALSE | H9: 7
A10: 8 | B10: Chen, Bo | C10: 1144 | D10: FALSE | E10: FALSE
A11: 9 | B11: Vine, Gail | C11: 1124 | D11: FALSE | E11: FALSE | F11: Share spot
A12: 10 | B12: Williams, John | C12: 1112 | D12: FALSE | E12: FALSE
A13: 11 | B13: Margetson, Andrew | C13: 1006 | D13: FALSE | E13: FALSE
A14: 12 | B14: Habib, Farhan | C14: 969 | D14: FALSE | E14: FALSE
A15: 13 | B15: Jones, Nathan | C15: 939 | D15: FALSE | E15: FALSE
A16: 14 | B16: Roughan, Angela | C16: 936 | D16: FALSE | E16: FALSE
A17: 15 | B17: Hubbard, Peter J | C17: 892 | D17: FALSE | E17: FALSE
A18: 16 | B18: Lim, Simon | C18: 821 | D18: FALSE | E18: FALSE
A19: 17 | B19: Rainer, Reece | C19: 807 | D19: FALSE | E19: FALSE
A20: 18 | B20: Primrose, Kyle | C20: 787 | D20: FALSE | E20: FALSE
A21: 19 | B21: Cronin, Angela | C21: 715 | D21: FALSE | E21: FALSE
A22: 20 | B22: Frith, Mark | C22: 684 | D22: FALSE | E22: FALSE
A23: 21 | B23: Coulter, Anthony | C23: 600 | D23: FALSE | E23: FALSE
A24: 22 | B24: Amodio, Peter | C24: 599 | D24: FALSE | E24: FALSE
A25: 23 | D25: FALSE | E25: FALSE
A26: 24 | D26: FALSE | E26: FALSE

Sheet Primary Members
A1: Rank | B1: Rating | C1: Name | D1: ID | E1: Last Played
A2: 1 | B2: 1581​±60 | C2: Lau, Yiu Yat | D2: 93912 | E2: 45724
A3: 2 | B3: 1512​±62 | C3: Williams, Peter | D3: 75080 | E3: 45754
A4: 3 | B4: 1494​±61 | C4: Malkov, Mark | D4: 26159 | E4: 45641
A5: 4 | B5: 1483​±70 | C5: Barrett, Scott | D5: 89042 | E5: 45747
A6: 5 | B6: 1463​±49 | C6: Graves, Darcy | D6: 84578 | E6: 45754
A7: 6 | B7: 1448​±44 | C7: Dao, Hung | D7: 73360 | E7: 45754
A8: 7 | B8: 1446​±44 | C8: Sachdeva, Dheeraj | D8: 144404 | E8: 45747
A9: 8 | B9: 1442​±42 | C9: Johnston, Yoko | D9: 79679 | E9: 45754
A10: 9 | B10: 1369​±45 | C10: Tran, Minh Khiem | D10: 101094 | E10: 45754
A11: 10 | B11: 1337​±116 | C11: Dunlop, Brent | D11: 84585 | E11: 45514
A12: 11 | B12: 1288​±50 | C12: Shrestha, Harish | D12: 155690 | E12: 45754
A13: 12 | B13: 1282​±64 | C13: Jenkinson, Chris | D13: 106764 | E13: 45641
... A68: 67 | B68: 406​±85 | C68: Chang, Zoe | D68: 148564 | E68: 45637
B69: 821​±54 | C69: Lim, Simon
B70: 684​±83 | C70: Frith, Mark

Sheet Draw
B2: Round 1 - 15/10 | D2: Round 2 - 22/10 | F2: Old 3 - 12/11 | H2: Old 4 - 5/11 | J2: Old 5 - 17/11 | L2: Old 6 - 29/10 | N2: Old 7 - 22/11 | U2: TEAM 1 | V2: TEAM 2 | W2: TEAM 3 | X2: TEAM 4 | Y2: TEAM 5 | Z2: TEAM 6 | AA2: TEAM 7 | AB2: TEAM 8
B3: TEAM 1 | C3: TEAM 8 | D3: TEAM 1 | E3: TEAM 2 | F3: TEAM 1 | G3: TEAM 3 | H3: TEAM 1 | I3: TEAM 7 | J3: TEAM 1 | K3: TEAM 4 | L3: TEAM 1 | M3: TEAM 5 | N3: TEAM 1 | O3: TEAM 6 | T3: TEAM 1
B4: TEAM 2 | C4: TEAM 3 | D4: TEAM 3 | E4: TEAM 4 | F4: TEAM 2 | G4: TEAM 4 | H4: TEAM 2 | I4: TEAM 8 | J4: TEAM 2 | K4: TEAM 7 | L4: TEAM 2 | M4: TEAM 6 | N4: TEAM 2 | O4: TEAM 5 | T4: TEAM 2 | U4: 2
B5: TEAM 4 | C5: TEAM 5 | D5: TEAM 5 | E5: TEAM 6 | F5: TEAM 5 | G5: TEAM 7 | H5: TEAM 3 | I5: TEAM 5 | J5: TEAM 3 | K5: TEAM 6 | L5: TEAM 3 | M5: TEAM 7 | N5: TEAM 3 | O5: TEAM 8 | T5: TEAM 3 | U5: 3 | V5: 1
B6: TEAM 6 | C6: TEAM 7 | D6: TEAM 7 | E6: TEAM 8 | F6: TEAM 6 | G6: TEAM 8 | H6: TEAM 4 | I6: TEAM 6 | J6: TEAM 5 | K6: TEAM 8 | L6: TEAM 4 | M6: TEAM 8 | N6: TEAM 4 | O6: TEAM 7 | T6: TEAM 4 | U6: 5 | V6: 3 | W6: 2
T7: TEAM 5 | U7: 6 | V7: 7 | W7: 4 | X7: 1
B8: Round 1 - 15/10 | D8: Round 2 - 22/10 | F8: Round 3 - 29/10 | H8: Round 4 - 5/11 | J8: Round 5 - 12/11 | L8: Round 6 - 19/11 | N8: Round 7 - 26/11 | P8: Finals? - 3/12 | T8: TEAM 6 | U8: 7 | V8: 6 | W8: 5 | X8: 4 | Y8: 2
B9: TEAM 1 | C9: TEAM 8 | D9: TEAM 1 | E9: TEAM 2 | F9: TEAM 1 | G9: TEAM 5 | H9: TEAM 1 | I9: TEAM 7 | J9: TEAM 1 | K9: TEAM 4 | L9: TEAM 3 | M9: TEAM 1 | N9: TEAM 1 | O9: TEAM 6 | T9: TEAM 7 | U9: 4 | V9: 5 | W9: 6 | X9: 7 | Y9: 3 | Z9: 1
B10: TEAM 2 | C10: TEAM 3 | D10: TEAM 3 | E10: TEAM 4 | F10: TEAM 2 | G10: TEAM 6 | H10: TEAM 2 | I10: TEAM 8 | J10: TEAM 2 | K10: TEAM 7 | L10: TEAM 8 | M10: TEAM 6 | N10: TEAM 2 | O10: TEAM 5 | T10: TEAM 8 | U10: 1 | V10: 4 | W10: 7 | X10: 6 | Y10: 5 | Z10: 3 | AA10: 2
B11: TEAM 4 | C11: TEAM 5 | D11: TEAM 5 | E11: TEAM 6 | F11: TEAM 3 | G11: TEAM 7 | H11: TEAM 3 | I11: TEAM 5 | J11: TEAM 3 | K11: TEAM 6 | L11: TEAM 5 | M11: TEAM 7 | N11: TEAM 3 | O11: TEAM 8
B12: TEAM 6 | C12: TEAM 7 | D12: TEAM 7 | E12: TEAM 8 | F12: TEAM 4 | G12: TEAM 8 | H12: TEAM 4 | I12: TEAM 6 | J12: TEAM 5 | K12: TEAM 8 | L12: TEAM 4 | M12: TEAM 2 | N12: TEAM 4 | O12: TEAM 7
B15: TEAM 1 | D15: TEAM 2 | F15: TEAM 3 | H15: TEAM 4 | J15: TEAM 5 | L15: TEAM 6 | N15: TEAM 7 | P15: TEAM 8
B16: P1 | C16: Darcy | D16: P1 | E16: Peter W | F16: P1 | G16: Dheeraj? | H16: P1 | I16: Harish | J16: P1 | K16: Chris | L16: P1 | M16: Michael R | N16: P1 | O16: George | P16: P1 | Q16: Richard G
B17: P2 | C17: Andrew | D17: P2 | E17: Rohit | F17: P2 | G17: Reece | H17: P2 | I17: Farhan | J17: P2 | K17: John | L17: P2 | M17: Paula | N17: P2 | O17: Nathan | P17: P2 | Q17: Bo C
B18: P3 | C18: Jaydon | D18: P3 | E18: Peter A | F18: P3 | G18: Richard M? | H18: P3 | I18: Simon | J18: P3 | K18: Angela | L18: P3 | M18: Michael C | N18: P3 | O18: Kyle | P18: P3 | Q18: Peter H

Sheet S-Sheets R1
B2: 2025 Spring Comp | I2: Date: | J2: 45945 | M2: Rnd: | N2: 1 | P2: Table: | Q2: 1
B4: HOME TEAM 1 | I4: AWAY TEAM 8 | Q4: Match | S4: Games | U4: Points | W4: Umpire
C5: Player's Name | D5: G1 | E5: G2 | F5: G3 | G5: G4 | H5: G5 | J5: Player's Name | K5: G1 | L5: G2 | M5: G3 | N5: G4 | O5: G5 | P5: Winner | Q5: Home | R5: Away | S5: Home | T5: Away | U5: Home | V5: Away
B6: P3 | C6: =VLOOKUP(B6, Teams!$B$11:$C$13, 2, FALSE) -> Jaydon | I6: P1 | J6: =VLOOKUP(I6, Teams!$P$11:$Q$13, 2, FALSE) -> Richard
B7: P1 | C7: =VLOOKUP(B7, Teams!$B$11:$C$13, 2, FALSE) -> Darcy | I7: P2 | J7: =VLOOKUP(I7, Teams!$P$11:$Q$13, 2, FALSE) -> Bo C
B8: P2 | C8: =VLOOKUP(B8, Teams!$B$11:$C$13, 2, FALSE) -> Andrew | I8: P3 | J8: =VLOOKUP(I8, Teams!$P$11:$Q$13, 2, FALSE) -> Peter H
B9: P3 | C9: =VLOOKUP(B9, Teams!$B$11:$C$13, 2, FALSE) -> Jaydon | I9: P2 | J9: =VLOOKUP(I9, Teams!$P$11:$Q$13, 2, FALSE) -> Bo C
B10: P2 | C10: =VLOOKUP(B10, Teams!$B$11:$C$13, 2, FALSE) -> Andrew | I10: P1 | J10: =VLOOKUP(I10, Teams!$P$11:$Q$13, 2, FALSE) -> Richard
B11: P1 | C11: =VLOOKUP(B11, Teams!$B$11:$C$13, 2, FALSE) -> Darcy | I11: P3 | J11: =VLOOKUP(I11, Teams!$P$11:$Q$13, 2, FALSE) -> Peter H
B12: P2 | C12: =VLOOKUP(B12, Teams!$B$11:$C$13, 2, FALSE) -> Andrew | I12: P2 | J12: =VLOOKUP(I12, Teams!$P$11:$Q$13, 2, FALSE) -> Bo C
B13: P3 | C13: =VLOOKUP(B13, Teams!$B$11:$C$13, 2, FALSE) -> Jaydon | I13: P3 | J13: =VLOOKUP(I13, Teams!$P$11:$Q$13, 2, FALSE) -> Peter H
B14: P1 | C14: =VLOOKUP(B14, Teams!$B$11:$C$13, 2, FALSE) -> Darcy | I14: P1 | J14: =VLOOKUP(I14, Teams!$P$11:$Q$13, 2, FALSE) -> Richard
B15: D | I15: D
P17: Totals:
P18: Winning Team:
B20: 2025 Spring Comp | I20: Date: | J20: 45945 | M20: Rnd: | N20: 1 | P20: Table: | Q20: 2
B22: HOME TEAM 2 | I22: AWAY TEAM 3 | Q22: Match | S22: Games | U22: Points | W22: Umpire
C23: Player's Name | D23: G1 | E23: G2 | F23: G3 | G23: G4 | H23: G5 | J23: Player's Name | K23: G1 | L23: G2 | M23: G3 | N23: G4 | O23: G5 | P23: Winner | Q23: Home | R23: Away | S23: Home | T23: Away | U23: Home | V23: Away
B24: P3 | C24: =VLOOKUP(B24, Teams!$D$11:$E$13, 2, FALSE) -> Peter A | I24: P1 | J24: =VLOOKUP(I24, Teams!$F$11:$G$13, 2, FALSE) -> Dheep
B25: P1 | C25: =VLOOKUP(B25, Teams!$D$11:$E$13, 2, FALSE) -> Peter W | I25: P2 | J25: =VLOOKUP(I25, Teams!$F$11:$G$13, 2, FALSE) -> Reece
B26: P2 | C26: =VLOOKUP(B26, Teams!$D$11:$E$13, 2, FALSE) -> Rohit | I26: P3 | J26: =VLOOKUP(I26, Teams!$F$11:$G$13, 2, FALSE) -> Tilly (R)
B27: P3 | C27: =VLOOKUP(B27, Teams!$D$11:$E$13, 2, FALSE) -> Peter A | I27: P2 | J27: =VLOOKUP(I27, Teams!$F$11:$G$13, 2, FALSE) -> Reece
B28: P2 | C28: =VLOOKUP(B28, Teams!$D$11:$E$13, 2, FALSE) -> Rohit | I28: P1 | J28: =VLOOKUP(I28, Teams!$F$11:$G$13, 2, FALSE) -> Dheep
B29: P1 | C29: =VLOOKUP(B29, Teams!$D$11:$E$13, 2, FALSE) -> Peter W | I29: P3 | J29: =VLOOKUP(I29, Teams!$F$11:$G$13, 2, FALSE) -> Tilly (R)
B30: P2 | C30: =VLOOKUP(B30, Teams!$D$11:$E$13, 2, FALSE) -> Rohit | I30: P2 | J30: =VLOOKUP(I30, Teams!$F$11:$G$13, 2, FALSE) -> Reece
B31: P3 | C31: =VLOOKUP(B31, Teams!$D$11:$E$13, 2, FALSE) -> Peter A | I31: P3 | J31: =VLOOKUP(I31, Teams!$F$11:$G$13, 2, FALSE) -> Tilly (R)
B32: P1 | C32: =VLOOKUP(B32, Teams!$D$11:$E$13, 2, FALSE) -> Peter W | I32: P1 | J32: =VLOOKUP(I32, Teams!$F$11:$G$13, 2, FALSE) -> Dheep
B33: D | I33: D
P35: Totals:
P36: Winning Team:
B38: 2025 Spring Comp | I38: Date: | J38: 45945 | M38: Rnd: | N38: 1 | P38: Table: | Q38: 3
B40: HOME TEAM 6 | I40: AWAY TEAM 7 | Q40: Match | S40: Games | U40: Points | W40: Umpire
C41: Player's Name | D41: G1 | E41: G2 | F41: G3 | G41: G4 | H41: G5 | J41: Player's Name | K41: G1 | L41: G2 | M41: G3 | N41: G4 | O41: G5 | P41: Winner | Q41: Home | R41: Away | S41: Home | T41: Away | U41: Home | V41: Away
B42: P3 | C42: =VLOOKUP(B42, Teams!$L$11:$M$13, 2, FALSE) -> Michael C | I42: P1 | J42: =VLOOKUP(I42, Teams!$N$11:$O$13, 2, FALSE) -> Bow (R)
B43: P1 | C43: =VLOOKUP(B43, Teams!$L$11:$M$13, 2, FALSE) -> Mick R | I43: P2 | J43: =VLOOKUP(I43, Teams!$N$11:$O$13, 2, FALSE) -> Nathan
B44: P2 | C44: =VLOOKUP(B44, Teams!$L$11:$M$13, 2, FALSE) -> Paula | I44: P3 | J44: =VLOOKUP(I44, Teams!$N$11:$O$13, 2, FALSE) -> Kyle
B45: P3 | C45: =VLOOKUP(B45, Teams!$L$11:$M$13, 2, FALSE) -> Michael C | I45: P2 | J45: =VLOOKUP(I45, Teams!$N$11:$O$13, 2, FALSE) -> Nathan
B46: P2 | C46: =VLOOKUP(B46, Teams!$L$11:$M$13, 2, FALSE) -> Paula | I46: P1 | J46: =VLOOKUP(I46, Teams!$N$11:$O$13, 2, FALSE) -> Bow (R)
B47: P1 | C47: =VLOOKUP(B47, Teams!$L$11:$M$13, 2, FALSE) -> Mick R | I47: P3 | J47: =VLOOKUP(I47, Teams!$N$11:$O$13, 2, FALSE) -> Kyle
B48: P2 | C48: =VLOOKUP(B48, Teams!$L$11:$M$13, 2, FALSE) -> Paula | I48: P2 | J48: =VLOOKUP(I48, Teams!$N$11:$O$13, 2, FALSE) -> Nathan
...

Sheet S-Sheets R2
B2: 2025 Spring Comp | I2: Date: | J2: 45952 | M2: Rnd: | N2: 2 | P2: Table: | Q2: 1
B4: HOME TEAM 1 | I4: AWAY TEAM 2 | Q4: Match | S4: Games | U4: Points | W4: Umpire
C5: Player's Name | D5: G1 | E5: G2 | F5: G3 | G5: G4 | H5: G5 | J5: Player's Name | K5: G1 | L5: G2 | M5: G3 | N5: G4 | O5: G5 | P5: Winner | Q5: Home | R5: Away | S5: Home | T5: Away | U5: Home | V5: Away
B6: P3 | C6: =VLOOKUP(B6, Teams!$B$11:$C$13, 2, FALSE) -> Jaydon | I6: P1 | J6: =VLOOKUP(I6, Teams!$D$11:$E$13, 2, FALSE) -> Peter W
B7: P1 | C7: =VLOOKUP(B7, Teams!$B$11:$C$13, 2, FALSE) -> Darcy | I7: P2 | J7: =VLOOKUP(I7, Teams!$D$11:$E$13, 2, FALSE) -> Rohit
B8: P2 | C8: =VLOOKUP(B8, Teams!$B$11:$C$13, 2, FALSE) -> Andrew | I8: P3 | J8: =VLOOKUP(I8, Teams!$D$11:$E$13, 2, FALSE) -> Peter A
B9: P3 | C9: =VLOOKUP(B9, Teams!$B$11:$C$13, 2, FALSE) -> Jaydon | I9: P2 | J9: =VLOOKUP(I9, Teams!$D$11:$E$13, 2, FALSE) -> Rohit
B10: P2 | C10: =VLOOKUP(B10, Teams!$B$11:$C$13, 2, FALSE) -> Andrew | I10: P1 | J10: =VLOOKUP(I10, Teams!$D$11:$E$13, 2, FALSE) -> Peter W
B11: P1 | C11: =VLOOKUP(B11, Teams!$B$11:$C$13, 2, FALSE) -> Darcy | I11: P3 | J11: =VLOOKUP(I11, Teams!$D$11:$E$13, 2, FALSE) -> Peter A
B12: P2 | C12: =VLOOKUP(B12, Teams!$B$11:$C$13, 2, FALSE) -> Andrew | I12: P2 | J12: =VLOOKUP(I12, Teams!$D$11:$E$13, 2, FALSE) -> Rohit
B13: P3 | C13: =VLOOKUP(B13, Teams!$B$11:$C$13, 2, FALSE) -> Jaydon | I13: P3 | J13: =VLOOKUP(I13, Teams!$D$11:$E$13, 2, FALSE) -> Peter A
B14: P1 | C14: =VLOOKUP(B14, Teams!$B$11:$C$13, 2, FALSE) -> Darcy | I14: P1 | J14: =VLOOKUP(I14, Teams!$D$11:$E$13, 2, FALSE) -> Peter W
B15: D | I15: D
P17: Totals:
P18: Winning Team:
B20: 2025 Spring Comp | I20: Date: | J20: 45945 | M20: Rnd: | N20: =N2 -> 2 | P20: Table: | Q20: 2
B22: HOME TEAM 3 | I22: AWAY TEAM 4 | Q22: Match | S22: Games | U22: Points | W22: Umpire
C23: Player's Name | D23: G1 | E23: G2 | F23: G3 | G23: G4 | H23: G5 | J23: Player's Name | K23: G1 | L23: G2 | M23: G3 | N23: G4 | O23: G5 | P23: Winner | Q23: Home | R23: Away | S23: Home | T23: Away | U23: Home | V23: Away
B24: P3 | C24: =VLOOKUP(B24, Teams!$F$11:$G$13, 2, FALSE) -> Tilly (R) | I24: P1 | J24: =VLOOKUP(I24, Teams!$H$11:$I$13, 2, FALSE) -> Harish
B25: P1 | C25: =VLOOKUP(B25, Teams!$F$11:$G$13, 2, FALSE) -> Dheep | I25: P2 | J25: =VLOOKUP(I25, Teams!$H$11:$I$13, 2, FALSE) -> Farhan
B26: P2 | C26: =VLOOKUP(B26, Teams!$F$11:$G$13, 2, FALSE) -> Reece | I26: P3 | J26: =VLOOKUP(I26, Teams!$H$11:$I$13, 2, FALSE) -> Simon
B27: P3 | C27: =VLOOKUP(B27, Teams!$F$11:$G$13, 2, FALSE) -> Tilly (R) | I27: P2 | J27: =VLOOKUP(I27, Teams!$H$11:$I$13, 2, FALSE) -> Farhan
B28: P2 | C28: =VLOOKUP(B28, Teams!$F$11:$G$13, 2, FALSE) -> Reece | I28: P1 | J28: =VLOOKUP(I28, Teams!$H$11:$I$13, 2, FALSE) -> Harish
B29: P1 | C29: =VLOOKUP(B29, Teams!$F$11:$G$13, 2, FALSE) -> Dheep | I29: P3 | J29: =VLOOKUP(I29, Teams!$H$11:$I$13, 2, FALSE) -> Simon
B30: P2 | C30: =VLOOKUP(B30, Teams!$F$11:$G$13, 2, FALSE) -> Reece | I30: P2 | J30: =VLOOKUP(I30, Teams!$H$11:$I$13, 2, FALSE) -> Farhan
B31: P3 | C31: =VLOOKUP(B31, Teams!$F$11:$G$13, 2, FALSE) -> Tilly (R) | I31: P3 | J31: =VLOOKUP(I31, Teams!$H$11:$I$13, 2, FALSE) -> Simon
B32: P1 | C32: =VLOOKUP(B32, Teams!$F$11:$G$13, 2, FALSE) -> Dheep | I32: P1 | J32: =VLOOKUP(I32, Teams!$H$11:$I$13, 2, FALSE) -> Harish
B33: D | I33: D
P35: Totals:
P36: Winning Team:
B38: 2025 Spring Comp | I38: Date: | J38: 45945 | M38: Rnd: | N38: =N2 -> 2 | P38: Table: | Q38: 3
B40: HOME TEAM 5 | I40: AWAY TEAM 6 | Q40: Match | S40: Games | U40: Points | W40: Umpire
C41: Player's Name | D41: G1 | E41: G2 | F41: G3 | G41: G4 | H41: G5 | J41: Player's Name | K41: G1 | L41: G2 | M41: G3 | N41: G4 | O41: G5 | P41: Winner | Q41: Home | R41: Away | S41: Home | T41: Away | U41: Home | V41: Away
B42: P3 | C42: =VLOOKUP(B42, Teams!$J$11:$K$13, 2, FALSE) -> Angela | I42: P1 | J42: =VLOOKUP(I42, Teams!$L$11:$M$13, 2, FALSE) -> Mick R
B43: P1 | C43: =VLOOKUP(B43, Teams!$J$11:$K$13, 2, FALSE) -> Aarya (R) | I43: P2 | J43: =VLOOKUP(I43, Teams!$L$11:$M$13, 2, FALSE) -> Paula
B44: P2 | C44: =VLOOKUP(B44, Teams!$J$11:$K$13, 2, FALSE) -> John | I44: P3 | J44: =VLOOKUP(I44, Teams!$L$11:$M$13, 2, FALSE) -> Michael C
B45: P3 | C45: =VLOOKUP(B45, Teams!$J$11:$K$13, 2, FALSE) -> Angela | I45: P2 | J45: =VLOOKUP(I45, Teams!$L$11:$M$13, 2, FALSE) -> Paula
B46: P2 | C46: =VLOOKUP(B46, Teams!$J$11:$K$13, 2, FALSE) -> John | I46: P1 | J46: =VLOOKUP(I46, Teams!$L$11:$M$13, 2, FALSE) -> Mick R
B47: P1 | C47: =VLOOKUP(B47, Teams!$J$11:$K$13, 2, FALSE) -> Aarya (R) | I47: P3 | J47: =VLOOKUP(I47, Teams!$L$11:$M$13, 2, FALSE) -> Michael C
B48: P2 | C48: =VLOOKUP(B48, Teams!$J$11:$K$13, 2, FALSE) -> John | I48: P2 | J48: =VLOOKUP(I48, Teams!$L$11:$M$13, 2, FALSE) -> Paula
...

Sheet S-Sheets R3
B2: 2025 Spring Comp | I2: Date: | J2: 45959 | M2: Rnd: | N2: 3 | P2: Table: | Q2: 1
B4: HOME TEAM 1 | I4: AWAY TEAM 5 | Q4: Match | S4: Games | U4: Points | W4: Umpire
C5: Player's Name | D5: G1 | E5: G2 | F5: G3 | G5: G4 | H5: G5 | J5: Player's Name | K5: G1 | L5: G2 | M5: G3 | N5: G4 | O5: G5 | P5: Winner | Q5: Home | R5: Away | S5: Home | T5: Away | U5: Home | V5: Away
B6: P3 | C6: =VLOOKUP(B6, Teams!$B$11:$C$13, 2, FALSE) -> Jaydon | I6: P1 | J6: =VLOOKUP(I6, Teams!$J$11:$K$13, 2, FALSE) -> Aarya (R)
B7: P1 | C7: =VLOOKUP(B7, Teams!$B$11:$C$13, 2, FALSE) -> Darcy | I7: P2 | J7: =VLOOKUP(I7, Teams!$J$11:$K$13, 2, FALSE) -> John
B8: P2 | C8: =VLOOKUP(B8, Teams!$B$11:$C$13, 2, FALSE) -> Andrew | I8: P3 | J8: =VLOOKUP(I8, Teams!$J$11:$K$13, 2, FALSE) -> Angela
B9: P3 | C9: =VLOOKUP(B9, Teams!$B$11:$C$13, 2, FALSE) -> Jaydon | I9: P2 | J9: =VLOOKUP(I9, Teams!$J$11:$K$13, 2, FALSE) -> John
B10: P2 | C10: =VLOOKUP(B10, Teams!$B$11:$C$13, 2, FALSE) -> Andrew | I10: P1 | J10: =VLOOKUP(I10, Teams!$J$11:$K$13, 2, FALSE) -> Aarya (R)
B11: P1 | C11: =VLOOKUP(B11, Teams!$B$11:$C$13, 2, FALSE) -> Darcy | I11: P3 | J11: =VLOOKUP(I11, Teams!$J$11:$K$13, 2, FALSE) -> Angela
B12: P2 | C12: =VLOOKUP(B12, Teams!$B$11:$C$13, 2, FALSE) -> Andrew | I12: P2 | J12: =VLOOKUP(I12, Teams!$J$11:$K$13, 2, FALSE) -> John
B13: P3 | C13: =VLOOKUP(B13, Teams!$B$11:$C$13, 2, FALSE) -> Jaydon | I13: P3 | J13: =VLOOKUP(I13, Teams!$J$11:$K$13, 2, FALSE) -> Angela
B14: P1 | C14: =VLOOKUP(B14, Teams!$B$11:$C$13, 2, FALSE) -> Darcy | I14: P1 | J14: =VLOOKUP(I14, Teams!$J$11:$K$13, 2, FALSE) -> Aarya (R)
B15: D | C15: =C14 -> Darcy | I15: D | J15: =J14 -> Aarya (R)
C16: =C12 -> Andrew | J16: =J12 -> John
P17: Totals:
P18: Winning Team:
B20: 2025 Spring Comp | I20: Date: | J20: 45945 | M20: Rnd: | N20: =N2 -> 3 | P20: Table: | Q20: 2
B22: HOME TEAM 2 | I22: AWAY TEAM 6 | Q22: Match | S22: Games | U22: Points | W22: Umpire
C23: Player's Name | D23: G1 | E23: G2 | F23: G3 | G23: G4 | H23: G5 | J23: Player's Name | K23: G1 | L23: G2 | M23: G3 | N23: G4 | O23: G5 | P23: Winner | Q23: Home | R23: Away | S23: Home | T23: Away | U23: Home | V23: Away
B24: P3 | C24: =VLOOKUP(B24, Teams!$D$11:$E$13, 2, FALSE) -> Peter A | I24: P1 | J24: =VLOOKUP(I24, Teams!$L$11:$M$13, 2, FALSE) -> Mick R
B25: P1 | C25: =VLOOKUP(B25, Teams!$D$11:$E$13, 2, FALSE) -> Peter W | I25: P2 | J25: =VLOOKUP(I25, Teams!$L$11:$M$13, 2, FALSE) -> Paula
B26: P2 | C26: =VLOOKUP(B26, Teams!$D$11:$E$13, 2, FALSE) -> Rohit | I26: P3 | J26: =VLOOKUP(I26, Teams!$L$11:$M$13, 2, FALSE) -> Michael C
B27: P3 | C27: =VLOOKUP(B27, Teams!$D$11:$E$13, 2, FALSE) -> Peter A | I27: P2 | J27: =VLOOKUP(I27, Teams!$L$11:$M$13, 2, FALSE) -> Paula
B28: P2 | C28: =VLOOKUP(B28, Teams!$D$11:$E$13, 2, FALSE) -> Rohit | I28: P1 | J28: =VLOOKUP(I28, Teams!$L$11:$M$13, 2, FALSE) -> Mick R
B29: P1 | C29: =VLOOKUP(B29, Teams!$D$11:$E$13, 2, FALSE) -> Peter W | I29: P3 | J29: =VLOOKUP(I29, Teams!$L$11:$M$13, 2, FALSE) -> Michael C
B30: P2 | C30: =VLOOKUP(B30, Teams!$D$11:$E$13, 2, FALSE) -> Rohit | I30: P2 | J30: =VLOOKUP(I30, Teams!$L$11:$M$13, 2, FALSE) -> Paula
B31: P3 | C31: =VLOOKUP(B31, Teams!$D$11:$E$13, 2, FALSE) -> Peter A | I31: P3 | J31: =VLOOKUP(I31, Teams!$L$11:$M$13, 2, FALSE) -> Michael C
B32: P1 | C32: =VLOOKUP(B32, Teams!$D$11:$E$13, 2, FALSE) -> Peter W | I32: P1 | J32: =VLOOKUP(I32, Teams!$L$11:$M$13, 2, FALSE) -> Mick R
B33: D | C33: =C32 -> Peter W | I33: D | J33: =J32 -> Mick R
C34: =C30 -> Rohit | J34: =J30 -> Paula
P35: Totals:
P36: Winning Team:
B38: 2025 Spring Comp | I38: Date: | J38: 45945 | M38: Rnd: | N38: =N2 -> 3 | P38: Table: | Q38: 3
B40: HOME TEAM 3 | I40: AWAY TEAM 7 | Q40: Match | S40: Games | U40: Points | W40: Umpire
C41: Player's Name | D41: G1 | E41: G2 | F41: G3 | G41: G4 | H41: G5 | J41: Player's Name | K41: G1 | L41: G2 | M41: G3 | N41: G4 | O41: G5 | P41: Winner | Q41: Home | R41: Away | S41: Home | T41: Away | U41: Home | V41: Away
B42: P3 | C42: =VLOOKUP(B42, Teams!$F$11:$G$13, 2, FALSE) -> Tilly (R) | I42: P1 | J42: =VLOOKUP(I42, Teams!$N$11:$O$13, 2, FALSE) -> Bow (R)
B43: P1 | C43: =VLOOKUP(B43, Teams!$F$11:$G$13, 2, FALSE) -> Dheep | I43: P2 | J43: =VLOOKUP(I43, Teams!$N$11:$O$13, 2, FALSE) -> Nathan
B44: P2 | C44: =VLOOKUP(B44, Teams!$F$11:$G$13, 2, FALSE) -> Reece | I44: P3 | J44: =VLOOKUP(I44, Teams!$N$11:$O$13, 2, FALSE) -> Kyle
B45: P3 | C45: =VLOOKUP(B45, Teams!$F$11:$G$13, 2, FALSE) -> Tilly (R) | I45: P2 | J45: =VLOOKUP(I45, Teams!$N$11:$O$13, 2, FALSE) -> Nathan
B46: P2 | C46: =VLOOKUP(B46, Teams!$F$11:$G$13, 2, FALSE) -> Reece | I46: P1 | J46: =VLOOKUP(I46, Teams!$N$11:$O$13, 2, FALSE) -> Bow (R)
...

Sheet S-Sheets R4
B2: 2025 Spring Comp | I2: Date: | J2: 45966 | M2: Rnd: | N2: 4 | P2: Table: | Q2: 1
B4: HOME TEAM 1 | I4: AWAY TEAM 7 | Q4: Match | S4: Games | U4: Points | W4: Umpire
C5: Player's Name | D5: G1 | E5: G2 | F5: G3 | G5: G4 | H5: G5 | J5: Player's Name | K5: G1 | L5: G2 | M5: G3 | N5: G4 | O5: G5 | P5: Winner | Q5: Home | R5: Away | S5: Home | T5: Away | U5: Home | V5: Away
B6: P3 | C6: =VLOOKUP(B6, Teams!$B$11:$C$13, 2, FALSE) -> Jaydon | I6: P1 | J6: =VLOOKUP(I6, Teams!$N$11:$O$13, 2, FALSE) -> Bow (R) | W6: Home
B7: P1 | C7: =VLOOKUP(B7, Teams!$B$11:$C$13, 2, FALSE) -> Darcy | I7: P2 | J7: =VLOOKUP(I7, Teams!$N$11:$O$13, 2, FALSE) -> Nathan | W7: Away
B8: P2 | C8: =VLOOKUP(B8, Teams!$B$11:$C$13, 2, FALSE) -> Andrew | I8: P3 | J8: =VLOOKUP(I8, Teams!$N$11:$O$13, 2, FALSE) -> Kyle | W8: Home
B9: P3 | C9: =VLOOKUP(B9, Teams!$B$11:$C$13, 2, FALSE) -> Jaydon | I9: P2 | J9: =VLOOKUP(I9, Teams!$N$11:$O$13, 2, FALSE) -> Nathan | W9: Away
B10: P2 | C10: =VLOOKUP(B10, Teams!$B$11:$C$13, 2, FALSE) -> Andrew | I10: P1 | J10: =VLOOKUP(I10, Teams!$N$11:$O$13, 2, FALSE) -> Bow (R) | W10: Home
B11: P1 | C11: =VLOOKUP(B11, Teams!$B$11:$C$13, 2, FALSE) -> Darcy | I11: P3 | J11: =VLOOKUP(I11, Teams!$N$11:$O$13, 2, FALSE) -> Kyle | W11: Away
B12: P2 | C12: =VLOOKUP(B12, Teams!$B$11:$C$13, 2, FALSE) -> Andrew | I12: P2 | J12: =VLOOKUP(I12, Teams!$N$11:$O$13, 2, FALSE) -> Nathan | W12: Home
B13: P3 | C13: =VLOOKUP(B13, Teams!$B$11:$C$13, 2, FALSE) -> Jaydon | I13: P3 | J13: =VLOOKUP(I13, Teams!$N$11:$O$13, 2, FALSE) -> Kyle | W13: Away
B14: P1 | C14: =VLOOKUP(B14, Teams!$B$11:$C$13, 2, FALSE) -> Darcy | I14: P1 | J14: =VLOOKUP(I14, Teams!$N$11:$O$13, 2, FALSE) -> Bow (R) | W14: Home
B15: D | C15: =C14 -> Darcy | I15: D | J15: =J14 -> Bow (R) | W15: Away Player 3
C16: =C12 -> Andrew | J16: =J12 -> Nathan
P17: Totals:
P18: Winning Team:
B20: 2025 Spring Comp | I20: Date: | J20: 45945 | M20: Rnd: | N20: =N2 -> 4 | P20: Table: | Q20: 2
B22: HOME TEAM 2 | I22: AWAY TEAM 8 | Q22: Match | S22: Games | U22: Points | W22: Umpire
C23: Player's Name | D23: G1 | E23: G2 | F23: G3 | G23: G4 | H23: G5 | J23: Player's Name | K23: G1 | L23: G2 | M23: G3 | N23: G4 | O23: G5 | P23: Winner | Q23: Home | R23: Away | S23: Home | T23: Away | U23: Home | V23: Away
B24: P3 | C24: =VLOOKUP(B24, Teams!$D$11:$E$13, 2, FALSE) -> Peter A | I24: P1 | J24: =VLOOKUP(I24, Teams!$P$11:$Q$13, 2, FALSE) -> Richard | W24: Home
B25: P1 | C25: =VLOOKUP(B25, Teams!$D$11:$E$13, 2, FALSE) -> Peter W | I25: P2 | J25: =VLOOKUP(I25, Teams!$P$11:$Q$13, 2, FALSE) -> Bo C | W25: Away
B26: P2 | C26: =VLOOKUP(B26, Teams!$D$11:$E$13, 2, FALSE) -> Rohit | I26: P3 | J26: =VLOOKUP(I26, Teams!$P$11:$Q$13, 2, FALSE) -> Peter H | W26: Home
B27: P3 | C27: =VLOOKUP(B27, Teams!$D$11:$E$13, 2, FALSE) -> Peter A | I27: P2 | J27: =VLOOKUP(I27, Teams!$P$11:$Q$13, 2, FALSE) -> Bo C | W27: Away
B28: P2 | C28: =VLOOKUP(B28, Teams!$D$11:$E$13, 2, FALSE) -> Rohit | I28: P1 | J28: =VLOOKUP(I28, Teams!$P$11:$Q$13, 2, FALSE) -> Richard | W28: Home
B29: P1 | C29: =VLOOKUP(B29, Teams!$D$11:$E$13, 2, FALSE) -> Peter W | I29: P3 | J29: =VLOOKUP(I29, Teams!$P$11:$Q$13, 2, FALSE) -> Peter H | W29: Away
B30: P2 | C30: =VLOOKUP(B30, Teams!$D$11:$E$13, 2, FALSE) -> Rohit | I30: P2 | J30: =VLOOKUP(I30, Teams!$P$11:$Q$13, 2, FALSE) -> Bo C | W30: Home
B31: P3 | C31: =VLOOKUP(B31, Teams!$D$11:$E$13, 2, FALSE) -> Peter A | I31: P3 | J31: =VLOOKUP(I31, Teams!$P$11:$Q$13, 2, FALSE) -> Peter H | W31: Away
B32: P1 | C32: =VLOOKUP(B32, Teams!$D$11:$E$13, 2, FALSE) -> Peter W | I32: P1 | J32: =VLOOKUP(I32, Teams!$P$11:$Q$13, 2, FALSE) -> Richard | W32: Home
B33: D | C33: =C32 -> Peter W | I33: D | J33: =J32 -> Richard | W33: Away Player 3
C34: =C30 -> Rohit | J34: =J30 -> Bo C
P35: Totals:
P36: Winning Team:
B38: 2025 Spring Comp | I38: Date: | J38: 45945 | M38: Rnd: | N38: =N2 -> 4 | P38: Table: | Q38: 3
B40: HOME TEAM 3 | I40: AWAY TEAM 5 | Q40: Match | S40: Games | U40: Points | W40: Umpire
C41: Player's Name | D41: G1 | E41: G2 | F41: G3 | G41: G4 | H41: G5 | J41: Player's Name | K41: G1 | L41: G2 | M41: G3 | N41: G4 | O41: G5 | P41: Winner | Q41: Home | R41: Away | S41: Home | T41: Away | U41: Home | V41: Away
B42: P3 | C42: =VLOOKUP(B42, Teams!$F$11:$G$13, 2, FALSE) -> Tilly (R) | I42: P1 | J42: =VLOOKUP(I42, Teams!$J$11:$K$13, 2, FALSE) -> Aarya (R) | W42: Home
B43: P1 | C43: =VLOOKUP(B43, Teams!$F$11:$G$13, 2, FALSE) -> Dheep | I43: P2 | J43: =VLOOKUP(I43, Teams!$J$11:$K$13, 2, FALSE) -> John | W43: Away
B44: P2 | C44: =VLOOKUP(B44, Teams!$F$11:$G$13, 2, FALSE) -> Reece | I44: P3 | J44: =VLOOKUP(I44, Teams!$J$11:$K$13, 2, FALSE) -> Angela | W44: Home
B45: P3 | C45: =VLOOKUP(B45, Teams!$F$11:$G$13, 2, FALSE) -> Tilly (R) | I45: P2 | J45: =VLOOKUP(I45, Teams!$J$11:$K$13, 2, FALSE) -> John | W45: Away
B46: P2 | C46: =VLOOKUP(B46, Teams!$F$11:$G$13, 2, FALSE) -> Reece | I46: P1 | J46: =VLOOKUP(I46, Teams!$J$11:$K$13, 2, FALSE) -> Aarya (R) | W46: Home
...

Sheet S-Sheets R5
B2: 2025 Spring Comp | I2: Date: | J2: 45973 | M2: Rnd: | N2: 5 | P2: Table: | Q2: 1
B4: HOME TEAM 1 | I4: AWAY TEAM 4 | Q4: Match | S4: Games | U4: Points | W4: Umpire
C5: Player's Name | D5: G1 | E5: G2 | F5: G3 | G5: G4 | H5: G5 | J5: Player's Name | K5: G1 | L5: G2 | M5: G3 | N5: G4 | O5: G5 | P5: Winner | Q5: Home | R5: Away | S5: Home | T5: Away | U5: Home | V5: Away
B6: P3 | C6: =VLOOKUP(B6, Teams!$B$11:$C$13, 2, FALSE) -> Jaydon | I6: P1 | J6: =VLOOKUP(I6, Teams!$H$11:$I$13, 2, FALSE) -> Harish | W6: Home
B7: P1 | C7: =VLOOKUP(B7, Teams!$B$11:$C$13, 2, FALSE) -> Darcy | I7: P2 | J7: =VLOOKUP(I7, Teams!$H$11:$I$13, 2, FALSE) -> Farhan | W7: Away
B8: P2 | C8: =VLOOKUP(B8, Teams!$B$11:$C$13, 2, FALSE) -> Andrew | I8: P3 | J8: =VLOOKUP(I8, Teams!$H$11:$I$13, 2, FALSE) -> Simon | W8: Home
B9: P3 | C9: =VLOOKUP(B9, Teams!$B$11:$C$13, 2, FALSE) -> Jaydon | I9: P2 | J9: =VLOOKUP(I9, Teams!$H$11:$I$13, 2, FALSE) -> Farhan | W9: Away
B10: P2 | C10: =VLOOKUP(B10, Teams!$B$11:$C$13, 2, FALSE) -> Andrew | I10: P1 | J10: =VLOOKUP(I10, Teams!$H$11:$I$13, 2, FALSE) -> Harish | W10: Home
B11: P1 | C11: =VLOOKUP(B11, Teams!$B$11:$C$13, 2, FALSE) -> Darcy | I11: P3 | J11: =VLOOKUP(I11, Teams!$H$11:$I$13, 2, FALSE) -> Simon | W11: Away
B12: P2 | C12: =VLOOKUP(B12, Teams!$B$11:$C$13, 2, FALSE) -> Andrew | I12: P2 | J12: =VLOOKUP(I12, Teams!$H$11:$I$13, 2, FALSE) -> Farhan | W12: Home
B13: P3 | C13: =VLOOKUP(B13, Teams!$B$11:$C$13, 2, FALSE) -> Jaydon | I13: P3 | J13: =VLOOKUP(I13, Teams!$H$11:$I$13, 2, FALSE) -> Simon | W13: Away
B14: P1 | C14: =VLOOKUP(B14, Teams!$B$11:$C$13, 2, FALSE) -> Darcy | I14: P1 | J14: =VLOOKUP(I14, Teams!$H$11:$I$13, 2, FALSE) -> Harish | W14: Home
B15: D | C15: =C14 -> Darcy | I15: D | J15: =J14 -> Harish | W15: Away Player 3
C16: =C12 -> Andrew | J16: =J12 -> Farhan
P17: Totals:
P18: Winning Team:
B20: 2025 Spring Comp | I20: Date: | J20: 45945 | M20: Rnd: | N20: =N2 -> 5 | P20: Table: | Q20: 2
B22: HOME TEAM 2 | I22: AWAY TEAM 7 | Q22: Match | S22: Games | U22: Points | W22: Umpire
C23: Player's Name | D23: G1 | E23: G2 | F23: G3 | G23: G4 | H23: G5 | J23: Player's Name | K23: G1 | L23: G2 | M23: G3 | N23: G4 | O23: G5 | P23: Winner | Q23: Home | R23: Away | S23: Home | T23: Away | U23: Home | V23: Away
B24: P3 | C24: =VLOOKUP(B24, Teams!$D$11:$E$13, 2, FALSE) -> Peter A | I24: P1 | J24: =VLOOKUP(I24, Teams!$N$11:$O$13, 2, FALSE) -> Bow (R) | W24: Home
B25: P1 | C25: =VLOOKUP(B25, Teams!$D$11:$E$13, 2, FALSE) -> Peter W | I25: P2 | J25: =VLOOKUP(I25, Teams!$N$11:$O$13, 2, FALSE) -> Nathan | W25: Away
B26: P2 | C26: =VLOOKUP(B26, Teams!$D$11:$E$13, 2, FALSE) -> Rohit | I26: P3 | J26: =VLOOKUP(I26, Teams!$N$11:$O$13, 2, FALSE) -> Kyle | W26: Home
B27: P3 | C27: =VLOOKUP(B27, Teams!$D$11:$E$13, 2, FALSE) -> Peter A | I27: P2 | J27: =VLOOKUP(I27, Teams!$N$11:$O$13, 2, FALSE) -> Nathan | W27: Away
B28: P2 | C28: =VLOOKUP(B28, Teams!$D$11:$E$13, 2, FALSE) -> Rohit | I28: P1 | J28: =VLOOKUP(I28, Teams!$N$11:$O$13, 2, FALSE) -> Bow (R) | W28: Home
B29: P1 | C29: =VLOOKUP(B29, Teams!$D$11:$E$13, 2, FALSE) -> Peter W | I29: P3 | J29: =VLOOKUP(I29, Teams!$N$11:$O$13, 2, FALSE) -> Kyle | W29: Away
B30: P2 | C30: =VLOOKUP(B30, Teams!$D$11:$E$13, 2, FALSE) -> Rohit | I30: P2 | J30: =VLOOKUP(I30, Teams!$N$11:$O$13, 2, FALSE) -> Nathan | W30: Home
B31: P3 | C31: =VLOOKUP(B31, Teams!$D$11:$E$13, 2, FALSE) -> Peter A | I31: P3 | J31: =VLOOKUP(I31, Teams!$N$11:$O$13, 2, FALSE) -> Kyle | W31: Away
B32: P1 | C32: =VLOOKUP(B32, Teams!$D$11:$E$13, 2, FALSE) -> Peter W | I32: P1 | J32: =VLOOKUP(I32, Teams!$N$11:$O$13, 2, FALSE) -> Bow (R) | W32: Home
B33: D | C33: =C32 -> Peter W | I33: D | J33: =J32 -> Bow (R) | W33: Away Player 3
C34: =C30 -> Rohit | J34: =J30 -> Nathan
P35: Totals:
P36: Winning Team:
B38: 2025 Spring Comp | I38: Date: | J38: 45945 | M38: Rnd: | N38: =N2 -> 5 | P38: Table: | Q38: 3
B40: HOME TEAM 6 | I40: AWAY TEAM 3 | Q40: Match | S40: Games | U40: Points | W40: Umpire
C41: Player's Name | D41: G1 | E41: G2 | F41: G3 | G41: G4 | H41: G5 | J41: Player's Name | K41: G1 | L41: G2 | M41: G3 | N41: G4 | O41: G5 | P41: Winner | Q41: Home | R41: Away | S41: Home | T41: Away | U41: Home | V41: Away
B42: P3 | C42: =VLOOKUP(B42, Teams!$L$11:$M$13, 2, FALSE) -> Michael C | I42: P1 | J42: =VLOOKUP(I42, Teams!$F$11:$G$13, 2, FALSE) -> Dheep | W42: Home
B43: P1 | C43: =VLOOKUP(B43, Teams!$L$11:$M$13, 2, FALSE) -> Mick R | I43: P2 | J43: =VLOOKUP(I43, Teams!$F$11:$G$13, 2, FALSE) -> Reece | W43: Away
B44: P2 | C44: =VLOOKUP(B44, Teams!$L$11:$M$13, 2, FALSE) -> Paula | I44: P3 | J44: =VLOOKUP(I44, Teams!$F$11:$G$13, 2, FALSE) -> Tilly (R) | W44: Home
B45: P3 | C45: =VLOOKUP(B45, Teams!$L$11:$M$13, 2, FALSE) -> Michael C | I45: P2 | J45: =VLOOKUP(I45, Teams!$F$11:$G$13, 2, FALSE) -> Reece | W45: Away
B46: P2 | C46: =VLOOKUP(B46, Teams!$L$11:$M$13, 2, FALSE) -> Paula | I46: P1 | J46: =VLOOKUP(I46, Teams!$F$11:$G$13, 2, FALSE) -> Dheep | W46: Home
...

Sheet S-Sheets R6
B2: 2025 Spring Comp | I2: Date: | J2: 45980 | M2: Rnd: | N2: 6 | P2: Table: | Q2: 1
B4: HOME TEAM 1 | I4: AWAY TEAM 3 | Q4: Match | S4: Games | U4: Points | W4: Umpire
C5: Player's Name | D5: G1 | E5: G2 | F5: G3 | G5: G4 | H5: G5 | J5: Player's Name | K5: G1 | L5: G2 | M5: G3 | N5: G4 | O5: G5 | P5: Winner | Q5: Home | R5: Away | S5: Home | T5: Away | U5: Home | V5: Away
B6: P3 | C6: =VLOOKUP(B6, Teams!$B$11:$C$13, 2, FALSE) -> Jaydon | I6: P1 | J6: =VLOOKUP(I6, Teams!$F$11:$G$13, 2, FALSE) -> Dheep | W6: Home
B7: P1 | C7: =VLOOKUP(B7, Teams!$B$11:$C$13, 2, FALSE) -> Darcy | I7: P2 | J7: =VLOOKUP(I7, Teams!$F$11:$G$13, 2, FALSE) -> Reece | W7: Away
B8: P2 | C8: =VLOOKUP(B8, Teams!$B$11:$C$13, 2, FALSE) -> Andrew | I8: P3 | J8: =VLOOKUP(I8, Teams!$F$11:$G$13, 2, FALSE) -> Tilly (R) | W8: Home
B9: P3 | C9: =VLOOKUP(B9, Teams!$B$11:$C$13, 2, FALSE) -> Jaydon | I9: P2 | J9: =VLOOKUP(I9, Teams!$F$11:$G$13, 2, FALSE) -> Reece | W9: Away
B10: P2 | C10: =VLOOKUP(B10, Teams!$B$11:$C$13, 2, FALSE) -> Andrew | I10: P1 | J10: =VLOOKUP(I10, Teams!$F$11:$G$13, 2, FALSE) -> Dheep | W10: Home
B11: P1 | C11: =VLOOKUP(B11, Teams!$B$11:$C$13, 2, FALSE) -> Darcy | I11: P3 | J11: =VLOOKUP(I11, Teams!$F$11:$G$13, 2, FALSE) -> Tilly (R) | W11: Away
B12: P2 | C12: =VLOOKUP(B12, Teams!$B$11:$C$13, 2, FALSE) -> Andrew | I12: P2 | J12: =VLOOKUP(I12, Teams!$F$11:$G$13, 2, FALSE) -> Reece | W12: Home
B13: P3 | C13: =VLOOKUP(B13, Teams!$B$11:$C$13, 2, FALSE) -> Jaydon | I13: P3 | J13: =VLOOKUP(I13, Teams!$F$11:$G$13, 2, FALSE) -> Tilly (R) | W13: Away
B14: P1 | C14: =VLOOKUP(B14, Teams!$B$11:$C$13, 2, FALSE) -> Darcy | I14: P1 | J14: =VLOOKUP(I14, Teams!$F$11:$G$13, 2, FALSE) -> Dheep | W14: Home
B15: D | C15: =C14 -> Darcy | I15: D | J15: =J14 -> Dheep | W15: Away Player 3
C16: =C12 -> Andrew | J16: =J12 -> Reece
P17: Totals:
P18: Winning Team:
B20: 2025 Spring Comp | I20: Date: | J20: 45945 | M20: Rnd: | N20: =N2 -> 6 | P20: Table: | Q20: 2
B22: HOME TEAM 6 | I22: AWAY TEAM 8 | Q22: Match | S22: Games | U22: Points | W22: Umpire
C23: Player's Name | D23: G1 | E23: G2 | F23: G3 | G23: G4 | H23: G5 | J23: Player's Name | K23: G1 | L23: G2 | M23: G3 | N23: G4 | O23: G5 | P23: Winner | Q23: Home | R23: Away | S23: Home | T23: Away | U23: Home | V23: Away
B24: P3 | C24: =VLOOKUP(B24, Teams!$L$11:$M$13, 2, FALSE) -> Michael C | I24: P1 | J24: =VLOOKUP(I24, Teams!$P$11:$Q$13, 2, FALSE) -> Richard | W24: Home
B25: P1 | C25: =VLOOKUP(B25, Teams!$L$11:$M$13, 2, FALSE) -> Mick R | I25: P2 | J25: =VLOOKUP(I25, Teams!$P$11:$Q$13, 2, FALSE) -> Bo C | W25: Away
B26: P2 | C26: =VLOOKUP(B26, Teams!$L$11:$M$13, 2, FALSE) -> Paula | I26: P3 | J26: =VLOOKUP(I26, Teams!$P$11:$Q$13, 2, FALSE) -> Peter H | W26: Home
B27: P3 | C27: =VLOOKUP(B27, Teams!$L$11:$M$13, 2, FALSE) -> Michael C | I27: P2 | J27: =VLOOKUP(I27, Teams!$P$11:$Q$13, 2, FALSE) -> Bo C | W27: Away
B28: P2 | C28: =VLOOKUP(B28, Teams!$L$11:$M$13, 2, FALSE) -> Paula | I28: P1 | J28: =VLOOKUP(I28, Teams!$P$11:$Q$13, 2, FALSE) -> Richard | W28: Home
B29: P1 | C29: =VLOOKUP(B29, Teams!$L$11:$M$13, 2, FALSE) -> Mick R | I29: P3 | J29: =VLOOKUP(I29, Teams!$P$11:$Q$13, 2, FALSE) -> Peter H | W29: Away
B30: P2 | C30: =VLOOKUP(B30, Teams!$L$11:$M$13, 2, FALSE) -> Paula | I30: P2 | J30: =VLOOKUP(I30, Teams!$P$11:$Q$13, 2, FALSE) -> Bo C | W30: Home
B31: P3 | C31: =VLOOKUP(B31, Teams!$L$11:$M$13, 2, FALSE) -> Michael C | I31: P3 | J31: =VLOOKUP(I31, Teams!$P$11:$Q$13, 2, FALSE) -> Peter H | W31: Away
B32: P1 | C32: =VLOOKUP(B32, Teams!$L$11:$M$13, 2, FALSE) -> Mick R | I32: P1 | J32: =VLOOKUP(I32, Teams!$P$11:$Q$13, 2, FALSE) -> Richard | W32: Home
B33: D | C33: =C32 -> Mick R | I33: D | J33: =J32 -> Richard | W33: Away Player 3
C34: =C30 -> Paula | J34: =J30 -> Bo C
P35: Totals:
P36: Winning Team:
B38: 2025 Spring Comp | I38: Date: | J38: 45945 | M38: Rnd: | N38: =N2 -> 6 | P38: Table: | Q38: 3
B40: HOME TEAM 5 | I40: AWAY TEAM 7 | Q40: Match | S40: Games | U40: Points | W40: Umpire
C41: Player's Name | D41: G1 | E41: G2 | F41: G3 | G41: G4 | H41: G5 | J41: Player's Name | K41: G1 | L41: G2 | M41: G3 | N41: G4 | O41: G5 | P41: Winner | Q41: Home | R41: Away | S41: Home | T41: Away | U41: Home | V41: Away
B42: P3 | C42: =VLOOKUP(B42, Teams!$J$11:$K$13, 2, FALSE) -> Angela | I42: P1 | J42: =VLOOKUP(I42, Teams!$N$11:$O$13, 2, FALSE) -> Bow (R) | W42: Home
B43: P1 | C43: =VLOOKUP(B43, Teams!$J$11:$K$13, 2, FALSE) -> Aarya (R) | I43: P2 | J43: =VLOOKUP(I43, Teams!$N$11:$O$13, 2, FALSE) -> Nathan | W43: Away
B44: P2 | C44: =VLOOKUP(B44, Teams!$J$11:$K$13, 2, FALSE) -> John | I44: P3 | J44: =VLOOKUP(I44, Teams!$N$11:$O$13, 2, FALSE) -> Kyle | W44: Home
B45: P3 | C45: =VLOOKUP(B45, Teams!$J$11:$K$13, 2, FALSE) -> Angela | I45: P2 | J45: =VLOOKUP(I45, Teams!$N$11:$O$13, 2, FALSE) -> Nathan | W45: Away
B46: P2 | C46: =VLOOKUP(B46, Teams!$J$11:$K$13, 2, FALSE) -> John | I46: P1 | J46: =VLOOKUP(I46, Teams!$N$11:$O$13, 2, FALSE) -> Bow (R) | W46: Home
...

Sheet SSheets R7
B2: 2025 Spring Comp | I2: Date: | J2: 45987 | M2: Rnd: | N2: 7 | P2: Table: | Q2: 1
B4: HOME TEAM 6 | I4: AWAY TEAM 1 | Q4: Match | S4: Games | U4: Points | W4: Umpire
C5: Player's Name | D5: G1 | E5: G2 | F5: G3 | G5: G4 | H5: G5 | J5: Player's Name | K5: G1 | L5: G2 | M5: G3 | N5: G4 | O5: G5 | P5: Winner | Q5: Home | R5: Away | S5: Home | T5: Away | U5: Home | V5: Away
B6: P3 | C6: =VLOOKUP(B6, Teams!$L$11:$M$13, 2, FALSE) -> Michael C | I6: P1 | J6: =VLOOKUP(I6, Teams!$B$11:$C$13, 2, FALSE) -> Darcy | W6: Home
B7: P1 | C7: =VLOOKUP(B7, Teams!$L$11:$M$13, 2, FALSE) -> Mick R | I7: P2 | J7: =VLOOKUP(I7, Teams!$B$11:$C$13, 2, FALSE) -> Andrew | W7: Away
B8: P2 | C8: =VLOOKUP(B8, Teams!$L$11:$M$13, 2, FALSE) -> Paula | I8: P3 | J8: =VLOOKUP(I8, Teams!$B$11:$C$13, 2, FALSE) -> Jaydon | W8: Home
B9: P3 | C9: =VLOOKUP(B9, Teams!$L$11:$M$13, 2, FALSE) -> Michael C | I9: P2 | J9: =VLOOKUP(I9, Teams!$B$11:$C$13, 2, FALSE) -> Andrew | W9: Away
B10: P2 | C10: =VLOOKUP(B10, Teams!$L$11:$M$13, 2, FALSE) -> Paula | I10: P1 | J10: =VLOOKUP(I10, Teams!$B$11:$C$13, 2, FALSE) -> Darcy | W10: Home
B11: P1 | C11: =VLOOKUP(B7, Teams!$L$11:$M$13, 2, FALSE) -> Mick R | I11: P3 | J11: =VLOOKUP(I11, Teams!$B$11:$C$13, 2, FALSE) -> Jaydon | W11: Away
B12: P2 | C12: =VLOOKUP(B12, Teams!$L$11:$M$13, 2, FALSE) -> Paula | I12: P2 | J12: =VLOOKUP(I12, Teams!$B$11:$C$13, 2, FALSE) -> Andrew | W12: Home
B13: P3 | C13: =VLOOKUP(B13, Teams!$L$11:$M$13, 2, FALSE) -> Michael C | I13: P3 | J13: =VLOOKUP(I13, Teams!$B$11:$C$13, 2, FALSE) -> Jaydon | W13: Away
B14: P1 | C14: =VLOOKUP(B7, Teams!$L$11:$M$13, 2, FALSE) -> Mick R | I14: P1 | J14: =VLOOKUP(I14, Teams!$B$11:$C$13, 2, FALSE) -> Darcy | W14: Home
B15: D | C15: =C14 -> Mick R | I15: D | J15: =J14 -> Darcy | W15: Away Player 3
C16: =C12 -> Paula | J16: =J12 -> Andrew
P17: Totals:
P18: Winning Team:
B20: 2025 Spring Comp | I20: Date: | J20: 45956 | M20: Rnd: | N20: =N2 -> 7 | P20: Table: | Q20: 2
B22: HOME TEAM 8 | I22: AWAY TEAM 3 | Q22: Match | S22: Games | U22: Points | W22: Umpire
C23: Player's Name | D23: G1 | E23: G2 | F23: G3 | G23: G4 | H23: G5 | J23: Player's Name | K23: G1 | L23: G2 | M23: G3 | N23: G4 | O23: G5 | P23: Winner | Q23: Home | R23: Away | S23: Home | T23: Away | U23: Home | V23: Away
B24: P3 | C24: =VLOOKUP(B24, Teams!$P$11:$Q$13, 2, FALSE) -> Peter H | I24: P1 | J24: =VLOOKUP(I24, Teams!$F$11:$G$13, 2, FALSE) -> Dheep | W24: Home
B25: P1 | C25: =VLOOKUP(B25, Teams!$P$11:$Q$13, 2, FALSE) -> Richard | I25: P2 | J25: =VLOOKUP(I25, Teams!$F$11:$G$13, 2, FALSE) -> Reece | W25: Away
B26: P2 | C26: =VLOOKUP(B26, Teams!$P$11:$Q$13, 2, FALSE) -> Bo C | I26: P3 | J26: =VLOOKUP(I26, Teams!$F$11:$G$13, 2, FALSE) -> Tilly (R) | W26: Home
B27: P3 | C27: =VLOOKUP(B27, Teams!$P$11:$Q$13, 2, FALSE) -> Peter H | I27: P2 | J27: =VLOOKUP(I27, Teams!$F$11:$G$13, 2, FALSE) -> Reece | W27: Away
B28: P2 | C28: =VLOOKUP(B28, Teams!$P$11:$Q$13, 2, FALSE) -> Bo C | I28: P1 | J28: =VLOOKUP(I28, Teams!$F$11:$G$13, 2, FALSE) -> Dheep | W28: Home
B29: P1 | C29: =VLOOKUP(B29, Teams!$P$11:$Q$13, 2, FALSE) -> Richard | I29: P3 | J29: =VLOOKUP(I29, Teams!$F$11:$G$13, 2, FALSE) -> Tilly (R) | W29: Away
B30: P2 | C30: =VLOOKUP(B30, Teams!$P$11:$Q$13, 2, FALSE) -> Bo C | I30: P2 | J30: =VLOOKUP(I30, Teams!$F$11:$G$13, 2, FALSE) -> Reece | W30: Home
B31: P3 | C31: =VLOOKUP(B31, Teams!$P$11:$Q$13, 2, FALSE) -> Peter H | I31: P3 | J31: =VLOOKUP(I31, Teams!$F$11:$G$13, 2, FALSE) -> Tilly (R) | W31: Away
B32: P1 | C32: =VLOOKUP(B32, Teams!$P$11:$Q$13, 2, FALSE) -> Richard | I32: P1 | J32: =VLOOKUP(I32, Teams!$F$11:$G$13, 2, FALSE) -> Dheep | W32: Home
B33: D | C33: =C32 -> Richard | I33: D | J33: =J32 -> Dheep | W33: Away Player 3
C34: =C30 -> Bo C | J34: =J30 -> Reece
P35: Totals:
P36: Winning Team:
B38: 2025 Spring Comp | I38: Date: | J38: 45956 | M38: Rnd: | N38: =N2 -> 7 | P38: Table: | Q38: 3
B40: HOME TEAM 7 | I40: AWAY TEAM 4 | Q40: Match | S40: Games | U40: Points | W40: Umpire
C41: Player's Name | D41: G1 | E41: G2 | F41: G3 | G41: G4 | H41: G5 | J41: Player's Name | K41: G1 | L41: G2 | M41: G3 | N41: G4 | O41: G5 | P41: Winner | Q41: Home | R41: Away | S41: Home | T41: Away | U41: Home | V41: Away
B42: P3 | C42: =VLOOKUP(B42, Teams!$N$11:$O$13, 2, FALSE) -> Kyle | I42: P1 | J42: =VLOOKUP(I42, Teams!$H$11:$I$13, 2, FALSE) -> Harish | W42: Home
B43: P1 | C43: =VLOOKUP(B43, Teams!$N$11:$O$13, 2, FALSE) -> Bow (R) | I43: P2 | J43: =VLOOKUP(I43, Teams!$H$11:$I$13, 2, FALSE) -> Farhan | W43: Away
B44: P2 | C44: =VLOOKUP(B44, Teams!$N$11:$O$13, 2, FALSE) -> Nathan | I44: P3 | J44: =VLOOKUP(I44, Teams!$H$11:$I$13, 2, FALSE) -> Simon | W44: Home
B45: P3 | C45: =VLOOKUP(B45, Teams!$N$11:$O$13, 2, FALSE) -> Kyle | I45: P2 | J45: =VLOOKUP(I45, Teams!$H$11:$I$13, 2, FALSE) -> Farhan | W45: Away
B46: P2 | C46: =VLOOKUP(B46, Teams!$N$11:$O$13, 2, FALSE) -> Nathan | I46: P1 | J46: =VLOOKUP(I46, Teams!$H$11:$I$13, 2, FALSE) -> Harish | W46: Home
...

Sheet Teams
A1: Mick
B2: TEAM 1 | E2: TEAM 2 | I2: TEAM 3 | M2: TEAM 4 | Q2: TEAM 5 | S2: TEAM 6 | U2: TEAM 7 | W2: TEAM 8 | AB2: Line 1 | AC2: Line 2 | AD2: Line 3 | AF2: Team Captain | AG2: Phone
B3: Graves, Darcy | C3: 1488 | E3: Williams, Peter | G3: 1427 | I3: Sachdeva, Dheeraj | K3: 1417 | M3: Shrestha, Harish | O3: 1292 | Q3: Jenkinson, Chris | R3: 1224 | S3: Rhodes, Michael | T3: 1220 | U3: Saperas, George | V3: 1191 | W3: Genet, Richard | X3: 1126 | AA3: TEAM 1 | AB3: Graves, Darcy | AC3: Margetson, Andrew | AD3: Richardson-Rigby, Jaydon | AF3: Graves, Darcy | AG3: 0410 171 998
B4: Margetson, Andrew | C4: 1107 | E4: Patidar, Rohit | G4: 974 | I4: Rainer, Reece | K4: 916 | M4: Habib, Farhan | O4: 987 | Q4: Williams, John | R4: 1044 | S4: Bertram, Paula | T4: 970 | U4: Jones, Nathan | V4: 985 | W4: Chen, Bo | X4: 1112 | AA4: TEAM 2 | AB4: Williams, Peter | AC4: Patidar, Rohit | AD4: Amodio, Peter | AF4: Williams, Peter | AG4: 4983 1114 | AH4: Number his father John
B5: Richardson-Rigby, Jaydon | C5: 480 | E5: Amodio, Peter | G5: 698 | I5: Matthews, Richard | K5: 740 | M5: Lim, Simon | O5: 766 | Q5: Cronin, Angela | R5: 780 | S5: Collins, Michael | T5: 801 | U5: Primrose, Kyle | V5: 823 | W5: Hubbard, Peter J | X5: 828 | AA5: TEAM 3 | AB5: Sachdeva, Dheeraj | AC5: Rainer, Reece | AD5: Matthews, Richard | AF5: Sachdeva, Dheeraj | AG5: 04500 023 212
C6: =SUM(C3:C5) -> 3075 | G6: =SUM(G3:G5) -> 3099 | K6: =SUM(K3:K5) -> 3073 | O6: =SUM(O3:O5) -> 3045 | R6: =SUM(R3:R5) -> 3048 | T6: =SUM(T3:T5) -> 2991 | V6: =SUM(V3:V5) -> 2999 | X6: =SUM(X3:X5) -> 3066 | Y6: 3049.5 | AA6: TEAM 4 | AB6: Shrestha, Harish | AC6: Habib, Farhan | AD6: Lim, Simon | AF6: Shrestha, Harish | AG6: 0412 771 055
AA7: TEAM 5 | AB7: Jenkinson, Chris | AC7: Williams, John | AD7: Cronin, Angela | AF7: Jenkinson, Chris | AG7: 0419 288 207
B8: Driving Score Sheets | AA8: TEAM 6 | AB8: Rhodes, Michael | AC8: Bertram, Paula | AD8: Collins, Michael | AF8: Rhodes, Michael | AG8: 0403 527 078
B10: TEAM 1 | D10: TEAM 2 | F10: TEAM 3 | H10: TEAM 4 | J10: TEAM 5 | L10: TEAM 6 | N10: TEAM 7 | P10: TEAM 8 | AA10: TEAM 7 | AB10: Saperas, George | AC10: Jones, Nathan | AD10: Primrose, Kyle
B11: P1 | C11: Darcy | D11: P1 | E11: Peter W | F11: P1 | G11: Dheep | H11: P1 | I11: Harish | J11: P1 | K11: Aarya (R) | L11: P1 | M11: Mick R | N11: P1 | O11: Bow (R) | P11: P1 | Q11: Richard | AA11: TEAM 8 | AB11: Genet, Richard | AC11: Chen, Bo | AD11: Hubbard, Peter J | AF11: Saperas, George | AG11: 0428 372 728
B12: P2 | C12: Andrew | D12: P2 | E12: Rohit | F12: P2 | G12: Reece | H12: P2 | I12: Farhan | J12: P2 | K12: John | L12: P2 | M12: Paula | N12: P2 | O12: Nathan | P12: P2 | Q12: Bo C | AF12: Genet, Richard | AG12: 0457 535 253
B13: P3 | C13: Jaydon | D13: P3 | E13: Peter A | F13: P3 | G13: Tilly (R) | H13: P3 | I13: Simon | J13: P3 | K13: Angela | L13: P3 | M13: Michael C | N13: P3 | O13: Kyle | P13: P3 | Q13: Peter H | AF13: Reserves
AF14: Johnston, Yoko | AG14: 0425 350 733
C15: Bow M (R) | G15: Yoko (R) | K15: Chris | AB15: Line 1 | AC15: Line 2 | AD15: Line 3 | AF15: Vine, Gail | AG15: 0423 453 327
G16: Minh (R) | AA16: TEAM 1 | AB16: Darcy | AC16: Andrew | AD16: Jaydon | AF16: Saperas, Harry | AG16: Refer to George
G17: Jimmy (R) | AA17: TEAM 2 | AB17: Peter W | AC17: Rohit | AD17: Peter A | AF17: Chang, Alex | AG17: 0449 106 485
G18: Richard M | AA18: TEAM 3 | AB18: Dheeraj | AC18: Reece | AD18: Richard M | AF18: Connor, Christina | AG18: 0422 386 433
AA19: TEAM 4 | AB19: Harish | AC19: Farhan | AD19: Simon | AF19: Frith, Mark | AG19: 0418 680 168
AA20: TEAM 5 | AB20: Chris | AC20: John | AD20: Angela
AA21: TEAM 6 | AB21: Michael R | AC21: Paula | AD21: Michael C
AA22: TEAM 7 | AB22: George | AC22: Nathan | AD22: Kyle
AA23: TEAM 8 | AB23: Richard G | AC23: Bo | AD23: Peter H

Sheet Results
C2: Round 1 | F2: Round 2 | I2: Round 3 | L2: Round 4 | O2: Round 5 | R2: Round 6 | U2: Round 7 | X2: Accumulative | AB2: Final Results | AK2: Round 7 Results | AL2: Home | AN2: Away | AO2: Winner | AP2: Match | AR2: Games
C3: Points | D3: Match | E3: Games | F3: Points | G3: Match | H3: Games | I3: Points | J3: Match | K3: Games | L3: Points | M3: Match | N3: Games | O3: Points | P3: Matches | Q3: Games | R3: Points | S3: Match | T3: Games | U3: Points | V3: Match | W3: Games | X3: Points | Y3: Matches | Z3: Games | AB3: Position | AD3: Points | AE3: Matches | AF3: Games | AG3: Players Round 7 | AL3: Team 6 | AM3: v | AN3: Team 1 | AO3: Team 6 | AP3: 5 | AQ3: 5 | AR3: 18 | AS3: 18 | AT3: Won on Points
B4: Team 2 | C4: 1 | D4: 5 | E4: 18 | F4: 1 | G4: 5 | H4: 17 | I4: 1 | J4: 7 | K4: 22 | L4: 1 | M4: 6 | N4: 20 | O4: 1 | P4: 5 | Q4: 16 | R4: 1 | S4: 6 | T4: 19 | U4: 1 | V4: 6 | W4: 20 | X4: =C4+F4+I4+L4+O4+R4+U4 -> 7 | Y4: =D4+G4+J4+M4+P4+S4+V4 -> 40 | Z4: =E4+H4+K4+N4+Q4+T4+W4 -> 132 | AB4: 1 | AC4: Team 2 | AD4: =X4 -> 7 | AE4: =Y4 -> 40 | AF4: =Z4 -> 132 | AG4: Peter W | AH4: Rohit | AI4: Peter A | AL4: Team 8 | AM4: v | AN4: Team 3 | AO4: Team 3 | AP4: 4 | AQ4: 5 | AR4: 16 | AS4: 15 | AT4: Doubles not played
B5: Team 4 | C5: 1 | D5: 7 | E5: 22 | F5: 1 | G5: 8 | H5: 24 | I5: 1 | J5: 5 | K5: 20 | L5: 1 | M5: 6 | N5: 19 | O5: 0 | P5: 4 | Q5: 18 | R5: 0 | S5: 4 | T5: 17 | U5: 1 | V5: 6 | W5: 20 | X5: =C5+F5+I5+L5+O5+R5+U5 -> 5 | Y5: =D5+G5+J5+M5+P5+S5+V5 -> 40 | Z5: =E5+H5+K5+N5+Q5+T5+W5 -> 140 | AB5: 2 | AC5: Team 4 | AD5: =X5 -> 5 | AE5: =Y5 -> 40 | AF5: =Z5 -> 140 | AG5: Harish | AH5: Farhan | AI5: Simon | AL5: Team 7 | AM5: v | AN5: Team 4 | AO5: Team 4 | AP5: 4 | AQ5: 6 | AR5: 17 | AS5: 20
B6: Team 1 | C6: 1 | D6: 7 | E6: 21 | F6: 0 | G6: 5 | H6: 16 | I6: 0 | J6: 4 | K6: 16 | L6: 1 | M6: 6 | N6: 19 | O6: 1 | P6: 6 | Q6: 18 | R6: 1 | S6: 6 | T6: 20 | U6: 0 | V6: 5 | W6: 18 | X6: =C6+F6+I6+L6+O6+R6+U6 -> 4 | Y6: =D6+G6+J6+M6+P6+S6+V6 -> 39 | Z6: =E6+H6+K6+N6+Q6+T6+W6 -> 128 | AB6: 3 | AC6: Team 1 | AD6: =X6 -> 4 | AE6: =Y6 -> 39 | AF6: =Z6 -> 128 | AG6: Darcy | AH6: Andrew | AI6: Jaydon | AL6: Team 5 | AM6: v | AN6: Team 2 | AO6: Team 2 | AP6: 4 | AQ6: 6 | AR6: 14 | AS6: 20
B7: Team 5 | C7: 0 | D7: 3 | E7: 14 | F7: 1 | G7: 5 | H7: 21 | I7: 1 | J7: 6 | K7: 19 | L7: 0 | M7: 5 | N7: 17 | O7: 1 | P7: 5 | Q7: 20 | R7: 1 | S7: 5 | T7: 18 | U7: 0 | V7: 4 | W7: 15 | X7: =C7+F7+I7+L7+O7+R7+U7 -> 4 | Y7: =D7+G7+J7+M7+P7+S7+V7 -> 33 | Z7: =E7+H7+K7+N7+Q7+T7+W7 -> 124 | AB7: 4 | AC7: Team 5 | AD7: =X7 -> 4 | AE7: =Y7 -> 33 | AF7: =Z7 -> 124 | AG7: Aarya (R) | AH7: John | AI7: Angela
B8: Team 3 | C8: 0 | D8: 5 | E8: 18 | F8: 0 | G8: 2 | H8: 9 | I8: 1 | J8: 3 | K8: 11 | L8: 1 | M8: 5 | N8: 18 | O8: 1 | P8: 6 | Q8: 19 | R8: 0 | S8: 4 | T8: 15 | U8: 1 | V8: 5 | W8: 17 | X8: =C8+F8+I8+L8+O8+R8+U8 -> 4 | Y8: =D8+G8+J8+M8+P8+S8+V8 -> 30 | Z8: =E8+H8+K8+N8+Q8+T8+W8 -> 107 | AB8: 5 | AC8: Team 3 | AD8: =X8 -> 4 | AE8: =Y8 -> 30 | AF8: =Z8 -> 107 | AG8: Dheep | AH8: Reece | AI8: Tilly (R)
B9: Team 8 | C9: 0 | D9: 2 | E9: 10 | F9: 1 | G9: 6 | H9: 20 | I9: 0 | J9: 5 | K9: 18 | L9: 0 | M9: 4 | N9: 16 | O9: 0 | P9: 5 | Q9: 16 | R9: 1 | S9: 7 | T9: 23 | U9: 0 | V9: 4 | W9: 14 | X9: =C9+F9+I9+L9+O9+R9+U9 -> 2 | Y9: =D9+G9+J9+M9+P9+S9+V9 -> 33 | Z9: =E9+H9+K9+N9+Q9+T9+W9 -> 117 | AB9: 6 | AC9: Team 8 | AD9: =X9 -> 2 | AE9: =Y9 -> 33 | AF9: =Z9 -> 117 | AG9: Richard | AH9: Bo C | AI9: Peter H
B10: Team 7 | C10: 1 | D10: 6 | E10: 21 | F10: 0 | G10: 4 | H10: 18 | I10: 0 | J10: 2 | K10: 7 | L10: 0 | M10: 4 | N10: 16 | O10: 0 | P10: 5 | Q10: 15 | R10: 0 | S10: 5 | T10: 16 | U10: 0 | V10: 4 | W10: 17 | X10: =C10+F10+I10+L10+O10+R10+U10 -> 1 | Y10: =D10+G10+J10+M10+P10+S10+V10 -> 30 | Z10: =E10+H10+K10+N10+Q10+T10+W10 -> 110 | AB10: 7 | AC10: Team 7 | AD10: =X10 -> 1 | AE10: =Y10 -> 30 | AF10: =Z10 -> 110 | AG10: Bow | AH10: Nathan | AI10: Kyle
B11: Team 6 | C11: 0 | D11: 4 | E11: 16 | F11: 0 | G11: 5 | H11: 19 | I11: 0 | J11: 3 | K11: 10 | L11: 0 | M11: 4 | N11: 16 | O11: 0 | P11: 4 | Q11: 14 | R11: 0 | S11: 3 | T11: 11 | U11: 1 | V11: 5 | W11: 18 | X11: =C11+F11+I11+L11+O11+R11+U11 -> 1 | Y11: =D11+G11+J11+M11+P11+S11+V11 -> 28 | Z11: =E11+H11+K11+N11+Q11+T11+W11 -> 104 | AB11: 8 | AC11: Team 6 | AD11: =X11 -> 1 | AE11: =Y11 -> 28 | AF11: =Z11 -> 104 | AG11: Michael R | AH11: Paula | AI11: Michael C
C12: =SUM(C4:C11) -> 4 | F12: =SUM(F4:F11) -> 4 | I12: =SUM(I4:I11) -> 4 | L12: =SUM(L4:L11) -> 4 | O12: =SUM(O4:O11) -> 4 | R12: =SUM(R4:R11) -> 4 | U12: =SUM(U4:U11) -> 4 | X12: =SUM(X4:X11) -> 28
A14: Check against Scoresheets
B15: Team 1 | C15: Team 2 | D15: Team 3 | E15: Team 4 | F15: Team 5 | G15: Team 6 | H15: Team 7 | I15: Team 8
A16: Rd 1 | B16: 21 | C16: 18 | D16: 18 | E16: 22 | F16: 14 | G16: 16 | H16: 21 | I16: 10
A17: Rd 2 | B17: 16 | C17: 17 | D17: 9 | E17: 24 | F17: 21 | G17: 19 | H17: 18 | I17: 20
A18: Rd 3 | B18: 16 | C18: 22 | D18: 11 | E18: 20 | F18: 19 | G18: 10 | H18: 7 | I18: 18
A20: Total | B20: =SUM(B16:B18) -> 53 | C20: =SUM(C16:C18) -> 57 | D20: =SUM(D16:D18) -> 38 | E20: =SUM(E16:E18) -> 66 | F20: =SUM(F16:F18) -> 54 | G20: =SUM(G16:G18) -> 45 | H20: =SUM(H16:H18) -> 46 | I20: =SUM(I16:I18) -> 48
A21: Yoko | B21: 53 | C21: 57 | D21: 38 | E21: 64 | F21: 54 | G21: 45 | H21: 46 | I21: 48

Sheet All
A1: Rank | B1: Rating | C1: Name | D1: ID | E1: Last Played
A2: 1 | B2: 1581​±60 | C2: Lau, Yiu Yat | D2: 93912 | E2: 45724
A3: 2 | B3: 1512​±62 | C3: Williams, Peter | D3: 75080 | E3: 45754
A4: 3 | B4: 1494​±61 | C4: Malkov, Mark | D4: 26159 | E4: 45641
A5: 4 | B5: 1483​±70 | C5: Barrett, Scott | D5: 89042 | E5: 45747
A6: 5 | B6: 1463​±49 | C6: Graves, Darcy | D6: 84578 | E6: 45754
A7: 6 | B7: 1448​±44 | C7: Dao, Hung | D7: 73360 | E7: 45754
A8: 7 | B8: 1446​±44 | C8: Sachdeva, Dheeraj | D8: 144404 | E8: 45747
A9: 8 | B9: 1442​±42 | C9: Johnston, Yoko | D9: 79679 | E9: 45754
A10: 9 | B10: 1369​±45 | C10: Tran, Minh Khiem | D10: 101094 | E10: 45754
A11: 10 | B11: 1337​±116 | C11: Dunlop, Brent | D11: 84585 | E11: 45514
A12: 11 | B12: 1288​±50 | C12: Shrestha, Harish | D12: 155690 | E12: 45754
A13: 12 | B13: 1282​±64 | C13: Jenkinson, Chris | D13: 106764 | E13: 45641
... A68: 67 | B68: 406​±85 | C68: Chang, Zoe | D68: 148564 | E68: 45637
C69: Habib, Farhan
C70: Patidar, Rohit
C71: Lim, Simon
